ERROR:root:code for hash md5 was not found.
Traceback (most recent call last):
  File "/global/apps/python/2.7.2/lib/python2.7/hashlib.py", line 139, in <module>
    globals()[__func_name] = __get_hash(__func_name)
  File "/global/apps/python/2.7.2/lib/python2.7/hashlib.py", line 91, in __get_builtin_constructor
    raise ValueError('unsupported hash type %s' % name)
ValueError: unsupported hash type md5
ERROR:root:code for hash sha1 was not found.
Traceback (most recent call last):
  File "/global/apps/python/2.7.2/lib/python2.7/hashlib.py", line 139, in <module>
    globals()[__func_name] = __get_hash(__func_name)
  File "/global/apps/python/2.7.2/lib/python2.7/hashlib.py", line 91, in __get_builtin_constructor
    raise ValueError('unsupported hash type %s' % name)
ValueError: unsupported hash type sha1
ERROR:root:code for hash sha224 was not found.
Traceback (most recent call last):
  File "/global/apps/python/2.7.2/lib/python2.7/hashlib.py", line 139, in <module>
    globals()[__func_name] = __get_hash(__func_name)
  File "/global/apps/python/2.7.2/lib/python2.7/hashlib.py", line 91, in __get_builtin_constructor
    raise ValueError('unsupported hash type %s' % name)
ValueError: unsupported hash type sha224
ERROR:root:code for hash sha256 was not found.
Traceback (most recent call last):
  File "/global/apps/python/2.7.2/lib/python2.7/hashlib.py", line 139, in <module>
    globals()[__func_name] = __get_hash(__func_name)
  File "/global/apps/python/2.7.2/lib/python2.7/hashlib.py", line 91, in __get_builtin_constructor
    raise ValueError('unsupported hash type %s' % name)
ValueError: unsupported hash type sha256
ERROR:root:code for hash sha384 was not found.
Traceback (most recent call last):
  File "/global/apps/python/2.7.2/lib/python2.7/hashlib.py", line 139, in <module>
    globals()[__func_name] = __get_hash(__func_name)
  File "/global/apps/python/2.7.2/lib/python2.7/hashlib.py", line 91, in __get_builtin_constructor
    raise ValueError('unsupported hash type %s' % name)
ValueError: unsupported hash type sha384
ERROR:root:code for hash sha512 was not found.
Traceback (most recent call last):
  File "/global/apps/python/2.7.2/lib/python2.7/hashlib.py", line 139, in <module>
    globals()[__func_name] = __get_hash(__func_name)
  File "/global/apps/python/2.7.2/lib/python2.7/hashlib.py", line 91, in __get_builtin_constructor
    raise ValueError('unsupported hash type %s' % name)
ValueError: unsupported hash type sha512
[SNIPER] WARNING: No SIFT connections made yet. Waiting...
[SNIPER] ERROR: Could not establish SIFT connection, aborting! Check benchmark-app*.log for errors.
